Workbook

Sheet README
A1: ASTS Valuation Model — MNO Direct-to-Device Revenue Only
A3: HOW TO USE
A4: All assumptions live on the Inputs tab. Edit only BLUE cells on YELLOW fill; every other cell is a formula.
A5: The Model tab shows the P&L waterfall, constellation economics, three valuation lenses, the blend, and sanity checks.
A6: The Stages tab shows what the company could be worth at different constellation stages, with stage-appropriate multiples.
A8: COLOR LEGEND
A9: Blue text on yellow fill = input you can change | Black = formula | Green = link to another sheet
A11: KEY MECHANICS (as specified by the model owner)
A12: revenue = subscribers(B) x ARPU($/mo) x 12 x revenue_share%
A13: gross_profit = revenue x gross_margin; ebitda = gross_profit - opex; ebit = ebitda - D&A
A14: net_income = pretax x (1 - tax) when pretax > 0
A15: eq_gross = GP x 11x - net_debt; eq_ebitda = EBITDA x 16x - net_debt; eq_pe = NI x 28x (already equity)
... A26: Model is steady-state (one representative year at scale), MNO D2D revenue only - no FirstNet/gov, no IoT.

Sheet Inputs
A1: INPUTS — edit blue cells on yellow only
A3: DEMAND
A4: Satellites in orbit | B4: 248 | C4: sats | D4: 45 = start of commercial coverage, 248 = FCC-granted full constellation
A5: Subscribers | B5: 1000 | C5: millions | D5: Range 100 - 2,000 (i.e., 100M to 2B subs)
A6: ARPU | B6: 5 | C6: $/sub/mo | D6: Range $2.50 - $5.00 per sub per month
A7: Revenue share to ASTS | B7: 1 | C7: % of ARPU | D7: 100% = ARPU is ASTS's cut; lower if ARPU is retail price shared with MNOs
A9: OPERATING ECONOMICS
A10: Gross margin | B10: 0.7 | C10: % of revenue | D10: Range 50% - 70%
A11: Opex | B11: 0.13 | C11: % of revenue | D11: Calibrated so base EBITDA = $34.2B
A12: Tax rate | B12: 0.21 | C12: % of pretax | D12: US federal statutory
A14: CONSTELLATION
A15: Worldwide constellation size | B15: 248 | C15: sats | D15: FCC-granted constellation, Apr 2026 - the model's full worldwide build
A16: Satellite lifespan | B16: 6 | C16: years | D16: Range 5 - 7 years
A17: Cost per satellite incl. launch | B17: 22.5 | C17: $M | D17: Range $20 - 25M all-in
A18: Ground/other D&A at full scale | B18: 5 | C18: $B/yr | D18: Calibration plug (gateways, gen-2 assets); scales with sats/248
A20: CAPITAL STRUCTURE
A21: Net debt | B21: 5 | C21: $B | D21: Update from latest filing
A22: Interest rate on net debt | B22: 0.08 | C22: % | D22: Blended cost of debt
A23: Shares outstanding | B23: 388 | C23: millions | D23: 388.12M as of Jul 22, 2026 (stockanalysis.com); raise for convert/warrant dilution
A25: VALUATION MULTIPLES & BLEND WEIGHTS
A26: EV / Gross Profit multiple | B26: 11 | C26: x | D26: Most generous lens - ignores everything below gross line
A27: EV / EBITDA multiple | B27: 16 | C27: x | D27: Blind to satellite replenishment (above D&A line)
A28: P/E multiple | B28: 28 | C28: x | D28: Only lens that absorbs D&A, interest, tax
A29: Blend weight - Net income (P/E) | B29: 0.5 | C29: weight | D29: Leans on the lens that sees capex
A30: Blend weight - EBITDA | B30: 0.35 | C30: weight
A31: Blend weight - Gross profit | B31: 0.15 | C31: weight
A33: SANITY-CHECK THRESHOLDS
A34: Max plausible revenue per sat | B34: 250 | C34: $M/sat/yr | D34: Flag if a sat must earn more than this per year
A35: Subscriber capacity per sat | B35: 8 | C35: M subs/sat | D35: No direct AST guidance; ~60 MNO deals cover 3B+ subs = ~12M/sat addressable at 248 - 8M is conservative
A36: Telecom EV/Revenue range | B36: 2x - 4x | D36: Mature telecom comps for reference
A38: MARKET REFERENCE (STATIC)
A39: Current share price | B39: 61.95 | C39: $/sh | D39: As of Jul 22, 2026 close - stockanalysis.com/stocks/asts
A40: Current market cap | B40: 24.04 | C40: $B | D40: price x 388.12M shares - consistency check for the cell above
A42: ADOPTION & TIME VALUE
A43: Years until subscriber target reached | B43: 6 | C43: years | D43: S-curve adoption - the valued steady-state year arrives this far out
A44: Discount rate | B44: 0.15 | C44: %/yr | D44: Pulls the steady-state value back to today; ~growth-equity hurdle
A46: DILUTION FROM CONVERTIBLE NOTES (AS OF JUL 22, 2026)
A47: Series | B47: Principal ($M) | C47: Conversion ($/sh) | D47: Shares if converted (M)
A48: 4.25% due 2032 (Jan '25; de minimis after Feb '26 repurchase; conv est.) | B48: 3.5 | C48: 27 | D48: =B48/C48 -> 0.12962963
A49: 2.375% due 2032 (Jul '25; capped call to $120.12) | B49: 325 | C49: 72.07 | D49: =B49/C49 -> 4.5095046
...

Sheet Model
A1: MODEL — one representative year at the chosen scale
A3: P&L WATERFALL ($B/yr)
A4: Revenue | B4: =Inputs!$B$5/1000*Inputs!$B$6*12*Inputs!$B$7 -> 60 | D4: subs(B) x ARPU x 12 x rev share
A5: Gross profit | B5: =B4*Inputs!$B$10 -> 42 | D5: revenue x gross margin
A6: Opex | B6: =B4*Inputs!$B$11 -> 7.8 | D6: revenue x opex %
A7: EBITDA | B7: =B5-B6 -> 34.2 | D7: gross profit - opex
A8: Fleet D&A | B8: =Inputs!$B$4*Inputs!$B$17/Inputs!$B$16/1000 -> 0.93 | D8: sats x cost per sat / lifespan (= replacement run-rate)
A9: Ground/other D&A | B9: =Inputs!$B$18*Inputs!$B$4/Inputs!$B$15 -> 5 | D9: scales with constellation completeness
A10: EBIT | B10: =B7-B8-B9 -> 28.27 | D10: ebitda - D&A
A11: Interest | B11: =Inputs!$B$21*Inputs!$B$22 -> 0.4 | D11: net debt x rate
A12: Pretax income | B12: =B10-B11 -> 27.87
A13: Net income | B13: =IF(B12>0,B12*(1-Inputs!$B$12),B12) -> 22.0173 | D13: taxed only when profitable
A15: CONSTELLATION ECONOMICS
A16: Replacement rate | B16: =Inputs!$B$4/Inputs!$B$16 -> 41.333333 | C16: sats/yr | D16: sats that must be replaced every year at this fleet size
A17: Replacement capex | B17: =B16*Inputs!$B$17/1000 -> 0.93 | C17: $B/yr | D17: annual spend just to stand still
A18: Sats remaining to worldwide | B18: =MAX(0,Inputs!$B$15-Inputs!$B$4) -> 0 | C18: sats | D18: deployments still needed to the 248-sat full build
A19: Capex to reach worldwide | B19: =B18*Inputs!$B$17/1000 -> 0 | C19: $B | D19: one-time build-out cost remaining
A20: Constellation gross book value | B20: =Inputs!$B$4*Inputs!$B$17/1000 -> 5.58 | C20: $B | D20: current fleet at cost
A22: VALUATION — THREE LENSES ($B equity value)
A23: 1. EV/Gross Profit lens | B23: =B5*Inputs!$B$26-Inputs!$B$21 -> 457 | D23: GP x multiple - net debt (ignores all costs below gross line)
A24: 2. EV/EBITDA lens | B24: =B7*Inputs!$B$27-Inputs!$B$21 -> 542.2 | D24: EBITDA x multiple - net debt (blind to replenishment capex)
A25: 3. P/E lens | B25: =B13*Inputs!$B$28 -> 616.4844 | D25: NI x multiple (already equity - sees D&A, interest, tax)
A26: Blended equity value (implied mkt cap) | B26: =(B25*Inputs!$B$29+B24*Inputs!$B$30+B23*Inputs!$B$31)/(Inputs!$B$29+Inputs!$B$30+Inputs!$B$31) -> 566.5622 | D26: 50/35/15 net/EBITDA/gross
A28: IMPLIED SHARE PRICE
A29: Price - EV/GP lens | B29: =B23*1000/Inputs!$B$55 -> 1099.3762 | C29: $/sh
A30: Price - EV/EBITDA lens | B30: =B24*1000/Inputs!$B$55 -> 1304.3365 | C30: $/sh
A31: Price - P/E lens | B31: =B25*1000/Inputs!$B$55 -> 1483.0378 | C31: $/sh
A32: Price - BLEND | B32: =B26*1000/Inputs!$B$55 -> 1362.9431 | C32: $/sh | D32: blend $B x 1e9 / effective diluted shares (Inputs B52)
A33: Upside vs current price | B33: =B32/Inputs!$B$39 -> 22.000696 | C33: x | D33: blend price / market reference price on Inputs
A35: SANITY CHECKS
A36: Revenue per sat (current fleet) | B36: =B4*1000/Inputs!$B$4 -> 241.93548 | C36: $M/sat/yr | D36: what each sat in orbit must earn
A37: Revenue per sat (at 248 full fleet) | B37: =B4*1000/Inputs!$B$15 -> 241.93548 | C37: $M/sat/yr | D37: revenue x 1000 / full 248 fleet (spec originally used 256)
A38: Rev/sat flag | B38: =IF(B36>Inputs!$B$34,"FLAG: exceeds max plausible $/sat - add sats or cut subs/ARPU","OK") -> OK
A39: EV / Revenue | B39: =(B26+Inputs!$B$21)/B4 -> 9.5260367 | C39: x | D39: mature telecom trades 2x - 4x; growth premium above that
A40: EV/Rev flag | B40: =IF(B39>4,"ABOVE telecom range (growth premium priced in)",IF(B39<2,"BELOW telecom range (conservative)","Within mature telecom 2x-4x")) -> ABOVE telecom range (growth premium priced in)
A41: Subscriber capacity of fleet | B41: =Inputs!$B$4*Inputs!$B$35 -> 1984 | C41: M subs | D41: sats x capacity per sat
A42: Capacity flag | B42: =IF(Inputs!$B$5>B41,"FLAG: subs exceed fleet capacity - needs more sats","OK") -> OK
A44: ADOPTION-ADJUSTED VALUE (PV)
A45: Discount factor | B45: =1/POWER(1+Inputs!$B$44,Inputs!$B$43) -> 0.4323276 | C45: x | D45: 1/(1+discount)^years - the price of waiting
A46: Value today (PV of blend price) | B46: =B32*B45 -> 589.23793 | C46: $/sh | D46: steady-state price discounted back - compare THIS to the market
...

Sheet Stages
A1: STAGES — what could it trade at across the constellation's life?
A2: Blue cells are stage assumptions you can edit (subs, ARPU, and stage-appropriate multiples: hypergrowth premium early, telecom compression at maturity). Opex %, margins, tax, capital structure pull from Inputs.
A4: Stage | B4: Sats | C4: Subs (M) | D4: ARPU | E4: GP mult | F4: EBITDA mult | G4: P/E mult | H4: Revenue ($B) | I4: EBITDA ($B) | J4: Net inc ($B) | K4: Eq: GP lens ($B) | L4: Eq: EBITDA ($B) | M4: Eq: P/E ($B) | N4: Blend ($B) | O4: Price ($/sh) | P4: Rev/sat ($M) | Q4: ETA (yrs) | R4: PV today ($/sh)
A5: Early commercial | B5: 45 | C5: 50 | D5: 3 | E5: 20 | F5: 30 | G5: 50 | H5: =C5/1000*D5*12*Inputs!$B$7 -> 1.8 | I5: =H5*(Inputs!$B$10-Inputs!$B$11) -> 1.026 | J5: =IF(H5*(Inputs!$B$10-Inputs!$B$11)-B5*Inputs!$B$17/Inputs!$B$16/1000-Inputs!$B$18*B5/Inputs!$B$15-Inputs!$B$21*Inputs!$B$22>0,(H5*(Inputs!$B$10-Inputs!$B$11)-B5*Inputs!$B$17/Inputs!$B$16/1000-Inputs!$B$18*B5/Inputs!$B$15-Inputs!$B$21*Inputs!$B$22)*(1-Inputs!$B$12),H5*(Inputs!$B$10-Inputs!$B$11)-B5*Inputs!$B$17/Inputs!$B$16/1000-Inputs!$B$18*B5/Inputs!$B$15-Inputs!$B$21*Inputs!$B$22) -> -0.45000806 | K5: =H5*Inputs!$B$10*E5-Inputs!$B$21 -> 20.2 | L5: =I5*F5-Inputs!$B$21 -> 25.78 | M5: =J5*G5 -> -22.500403 | N5: =(M5*Inputs!$B$29+L5*Inputs!$B$30+K5*Inputs!$B$31)/(Inputs!$B$29+Inputs!$B$30+Inputs!$B$31) -> 0.80279839 | O5: =N5*1000/Inputs!$B$55 -> 1.9312417 | P5: =H5*1000/B5 -> 40 | Q5: 1 | R5: =O5/POWER(1+Inputs!$B$44,Q5) -> 1.6793406
A6: Continental coverage | B6: 90 | C6: 150 | D6: 3.5 | E6: 16 | F6: 24 | G6: 40 | H6: =C6/1000*D6*12*Inputs!$B$7 -> 6.3 | I6: =H6*(Inputs!$B$10-Inputs!$B$11) -> 3.591 | J6: =IF(H6*(Inputs!$B$10-Inputs!$B$11)-B6*Inputs!$B$17/Inputs!$B$16/1000-Inputs!$B$18*B6/Inputs!$B$15-Inputs!$B$21*Inputs!$B$22>0,(H6*(Inputs!$B$10-Inputs!$B$11)-B6*Inputs!$B$17/Inputs!$B$16/1000-Inputs!$B$18*B6/Inputs!$B$15-Inputs!$B$21*Inputs!$B$22)*(1-Inputs!$B$12),H6*(Inputs!$B$10-Inputs!$B$11)-B6*Inputs!$B$17/Inputs!$B$16/1000-Inputs!$B$18*B6/Inputs!$B$15-Inputs!$B$21*Inputs!$B$22) -> 0.82079726 | K6: =H6*Inputs!$B$10*E6-Inputs!$B$21 -> 65.56 | L6: =I6*F6-Inputs!$B$21 -> 81.184 | M6: =J6*G6 -> 32.83189 | N6: =(M6*Inputs!$B$29+L6*Inputs!$B$30+K6*Inputs!$B$31)/(Inputs!$B$29+Inputs!$B$30+Inputs!$B$31) -> 54.664345 | O6: =N6*1000/Inputs!$B$55 -> 131.50259 | P6: =H6*1000/B6 -> 70 | Q6: 2.5 | R6: =O6/POWER(1+Inputs!$B$44,Q6) -> 92.723473
A7: Near-global | B7: 168 | C7: 500 | D7: 4 | E7: 13 | F7: 19 | G7: 32 | H7: =C7/1000*D7*12*Inputs!$B$7 -> 24 | I7: =H7*(Inputs!$B$10-Inputs!$B$11) -> 13.68 | J7: =IF(H7*(Inputs!$B$10-Inputs!$B$11)-B7*Inputs!$B$17/Inputs!$B$16/1000-Inputs!$B$18*B7/Inputs!$B$15-Inputs!$B$21*Inputs!$B$22>0,(H7*(Inputs!$B$10-Inputs!$B$11)-B7*Inputs!$B$17/Inputs!$B$16/1000-Inputs!$B$18*B7/Inputs!$B$15-Inputs!$B$21*Inputs!$B$22)*(1-Inputs!$B$12),H7*(Inputs!$B$10-Inputs!$B$11)-B7*Inputs!$B$17/Inputs!$B$16/1000-Inputs!$B$18*B7/Inputs!$B$15-Inputs!$B$21*Inputs!$B$22) -> 7.3176935 | K7: =H7*Inputs!$B$10*E7-Inputs!$B$21 -> 213.4 | L7: =I7*F7-Inputs!$B$21 -> 254.92 | M7: =J7*G7 -> 234.16619 | N7: =(M7*Inputs!$B$29+L7*Inputs!$B$30+K7*Inputs!$B$31)/(Inputs!$B$29+Inputs!$B$30+Inputs!$B$31) -> 238.3151 | O7: =N7*1000/Inputs!$B$55 -> 573.29968 | P7: =H7*1000/B7 -> 142.85714 | Q7: 4 | R7: =O7/POWER(1+Inputs!$B$44,Q7) -> 327.78595
A8: Worldwide (base case) | B8: 248 | C8: 1000 | D8: 5 | E8: 11 | F8: 16 | G8: 28 | H8: =C8/1000*D8*12*Inputs!$B$7 -> 60 | I8: =H8*(Inputs!$B$10-Inputs!$B$11) -> 34.2 | J8: =IF(H8*(Inputs!$B$10-Inputs!$B$11)-B8*Inputs!$B$17/Inputs!$B$16/1000-Inputs!$B$18*B8/Inputs!$B$15-Inputs!$B$21*Inputs!$B$22>0,(H8*(Inputs!$B$10-Inputs!$B$11)-B8*Inputs!$B$17/Inputs!$B$16/1000-Inputs!$B$18*B8/Inputs!$B$15-Inputs!$B$21*Inputs!$B$22)*(1-Inputs!$B$12),H8*(Inputs!$B$10-Inputs!$B$11)-B8*Inputs!$B$17/Inputs!$B$16/1000-Inputs!$B$18*B8/Inputs!$B$15-Inputs!$B$21*Inputs!$B$22) -> 22.0173 | K8: =H8*Inputs!$B$10*E8-Inputs!$B$21 -> 457 | L8: =I8*F8-Inputs!$B$21 -> 542.2 | M8: =J8*G8 -> 616.4844 | N8: =(M8*Inputs!$B$29+L8*Inputs!$B$30+K8*Inputs!$B$31)/(Inputs!$B$29+Inputs!$B$30+Inputs!$B$31) -> 566.5622 | O8: =N8*1000/Inputs!$B$55 -> 1362.9431 | P8: =H8*1000/B8 -> 241.93548 | Q8: 6 | R8: =O8/POWER(1+Inputs!$B$44,Q8) -> 589.23793
A9: Mature / saturated | B9: 248 | C9: 1500 | D9: 5 | E9: 8 | F9: 11 | G9: 18 | H9: =C9/1000*D9*12*Inputs!$B$7 -> 90 | I9: =H9*(Inputs!$B$10-Inputs!$B$11) -> 51.3 | J9: =IF(H9*(Inputs!$B$10-Inputs!$B$11)-B9*Inputs!$B$17/Inputs!$B$16/1000-Inputs!$B$18*B9/Inputs!$B$15-Inputs!$B$21*Inputs!$B$22>0,(H9*(Inputs!$B$10-Inputs!$B$11)-B9*Inputs!$B$17/Inputs!$B$16/1000-Inputs!$B$18*B9/Inputs!$B$15-Inputs!$B$21*Inputs!$B$22)*(1-Inputs!$B$12),H9*(Inputs!$B$10-Inputs!$B$11)-B9*Inputs!$B$17/Inputs!$B$16/1000-Inputs!$B$18*B9/Inputs!$B$15-Inputs!$B$21*Inputs!$B$22) -> 35.5263 | K9: =H9*Inputs!$B$10*E9-Inputs!$B$21 -> 499 | L9: =I9*F9-Inputs!$B$21 -> 559.3 | M9: =J9*G9 -> 639.4734 | N9: =(M9*Inputs!$B$29+L9*Inputs!$B$30+K9*Inputs!$B$31)/(Inputs!$B$29+Inputs!$B$30+Inputs!$B$31) -> 590.3417 | O9: =N9*1000/Inputs!$B$55 -> 1420.148 | P9: =H9*1000/B9 -> 362.90323 | Q9: 9 | R9: =O9/POWER(1+Inputs!$B$44,Q9) -> 403.69469
A11: Stage subs/ARPU/multiples are illustrative editable assumptions from the model owner's framework: growth multiples compress as the story de-risks and growth slows.

Sheet Partners
A1: PARTNERS - ~60 MNO agreements covering 3B+ combined subscribers (AST)
A3: Partner | B3: Region | C3: Subs (M) | D3: % of 3B | E3: Agreement / status
A4: Vodafone Group | B4: Europe / Africa | C4: 265 | D4: =C4/3000 -> 0.088333333 | E4: Definitive; SatCo JV for Europe; investor
A5: Vodafone Idea (Vi) | B5: India | C5: 200 | D5: =C5/3000 -> 0.066666667 | E5: Announced partner
A6: Verizon | B6: United States | C6: 146 | D6: =C6/3000 -> 0.048666667 | E6: Definitive commercial agreement; service from 2026
A7: AT&T | B7: United States | C7: 118 | D7: =C7/3000 -> 0.039333333 | E7: Definitive commercial agreement; investor
A8: stc group | B8: Saudi / MENA | C8: 25 | D8: =C8/3000 -> 0.0083333333 | E8: Partner; 13 subsidiaries across MENA/Europe
A9: TELUS | B9: Canada | C9: 10 | D9: =C9/3000 -> 0.0033333333 | E9: Partner (21M total connections)
A10: Bell | B10: Canada | C10: 10 | D10: =C10/3000 -> 0.0033333333 | E10: Partner; investor (BCE)
A11: Rakuten Mobile | B11: Japan | C11: 7 | D11: =C11/3000 -> 0.0023333333 | E11: Founding strategic investor (group: 1.6B members)
A12: Named subtotal | C12: =SUM(C4:C11) -> 781 | D12: =C12/3000 -> 0.26033333
A13: All agreements (AST) | C13: 3000 | E13: ~60 MNOs; $1.2B+ contracted revenue committed to date
A15: Your target penetration | C15: =Inputs!$B$5/C13 -> 0.33333333 | E15: Inputs subscribers / 3B partnered base - the subs input is a penetration assumption on this pool
A16: Fleet capacity cross-check | C16: =Inputs!$B$15*Inputs!$B$35 -> 1984 | E16: 248 sats x capacity per sat (M subs) - addressable exceeds capacity, so satellites are the bottleneck
A18: Subscriber figures are each operator's public totals (approximate, mid-2025/26) - the pool AST can sell into,
A19: not users AST has signed. Rakuten's 1.6B 'members' is its e-commerce ecosystem; the mobile base (~7M) is used here.
A20: Sources: ast-science.com/partners | Q1 2026 business update (~60 agreements, 3B+ subs, $1.2B+ contracted)
A21: | Via Satellite Oct 2025 (Verizon commercial agreement).

Sheet Underwriting
A1: UNDERWRITING NOTES - what each piece of this model is betting on
A3: THE THREE LENSES
A4: 1. EV/Gross Profit x11: anchors on gross profit, before any operating or capital cost. Most generous by construction;
A5: blind to everything that makes a satellite business hard. This is how pre-scale infrastructure gets pitched.
A6: 2. EV/EBITDA x16: absorbs opex but sits above the D&A line, so it never sees that the revenue-generating asset burns up
A7: every 5-7 years. Structurally overstates cash generation for a consumable fleet. 16x = premium infra multiple.
A8: 3. P/E x28: net income has already paid for depreciation (= satellite replenishment), interest and tax. The only honest
A9: lens for this business; produces the lowest value. 28x = quality-growth-compounder multiple.
A10: BLEND 50/35/15 (net/EBITDA/gross): majority weight on P/E because it is the only lens that pays for the capex.
A12: STAGE-BY-STAGE (fleet anchors are AST's own guidance)
A13: Early commercial, 45 sats: low end of AST's 45-60 guidance for continuous US & select-market coverage. 50M subs at
A14: $3.00 intro ARPU; hypergrowth multiples (50x P/E); earnings near zero so blended value is small or negative.
... A72: Financing/build-out cash-flow simulation lives in the companion HTML app (Financing tab), not in this workbook.
